Workbook

Sheet فرم نقشه برداری
F1: گزارش عملیات نقشه برداری میسر بهار | P1: تاریخ: | Q1: =DATA!E1 -> 06/07 | R1: 1405/ | T1: کد فرم TF 100
A2: پروژه احداث تونل و کانال کابل ارتباطی | P2: ایام : | Q2: =DATA!E2 -> شنبه
A3: نام شفت | C3: مانده | D3: سمت | E3: فعالیت | F3: کیلومتراژ قبلی | G3: کیلومتراژ فعلی | H3: پیشرفت روزانه | I3: پیشرفت از شفت | J3: مانده
A4: شفت 1 | B4: 362.1 | C4: =B4-227 -> 135.1 | D4: اتصال | E4: جبهه کاری حفاری | F4: =(LOOKUP(DATA!D4,DATA!K2:K1494,DATA!L2:L1494))+(DATA!E4/100) -> 355.3 | G4: =(LOOKUP(DATA!F4,DATA!K2:K1494,DATA!L2:L1494))+DATA!G4/100 -> 354.34 | H4: =F4-G4 -> 0.96 | I4: =B4-G4 -> 7.76 | J4: =G4-227 -> 127.34 | L4: 1 | M4: 2 | N4: 3 | O4: 4 | P4: 5 | Q4: 6 | R4: 7
K5: انحراف | X5: =G4 -> 354.34 | Y5: =H4 -> 0.96
X6: =G12 -> 367.49 | Y6: =H12 -> 1.18
E7: نصب 3D یا قاب | F7: =F4 -> 355.3 | G7: =G4 -> 354.34 | H7: =H4 -> 0.96 | I7: =I4 -> 7.76 | K7: ریزش | X7: =G20 -> 584.95 | Y7: =H20 -> 0.85
V8: ` | X8: =G28 -> 588.25 | Y8: =H28 -> 0
L9: 1 | M9: 2 | N9: 3 | O9: 4 | P9: 5 | Q9: 6 | R9: 7 | X9: =G36 -> 909.8 | Y9: =H36 -> 0
E10: اجرای شاتکریت نهائی | F10: =F4 -> 355.3 | G10: =G4 -> 354.34 | H10: =H4 -> 0.96 | I10: =I4 -> 7.76 | K10: انحراف | X10: =G44 -> 909.8 | Y10: =H44 -> 0
X11: =G52 -> 1200 | Y11: =H52 -> 0
C12: =B20-B4 -> 224.55 | D12: شفت 2 | E12: جبهه کاری حفاری | F12: =(LOOKUP(DATA!D7,DATA!K2:K1494,DATA!L2:L1494))+DATA!E7/100 -> 366.31 | G12: =(LOOKUP(DATA!F7,DATA!K2:K1494,DATA!L2:L1494))+DATA!G7/100 -> 367.49 | H12: =G12-F12 -> 1.18 | I12: =G12-B4 -> 5.39 | J12: =(B20-B4)-(I20+I12) -> 217.46 | L12: 1 | M12: 2 | N12: 3 | O12: 4 | P12: 5 | Q12: 6 | R12: 7 | X12: =G60 -> 1200 | Y12: =H60 -> 0
K13: انحراف
E15: نصب 3D یا قاب | F15: =F12 -> 366.31 | G15: =G12 -> 367.49 | H15: =H12 -> 1.18 | I15: =I12 -> 5.39 | K15: ریزش
L17: 1 | M17: 2 | N17: 3 | O17: 4 | P17: 5 | Q17: 6 | R17: 7
E18: اجرای شاتکریت نهائی | F18: =F12 -> 366.31 | G18: =G12 -> 367.49 | H18: =H12 -> 1.18 | I18: =I12 -> 5.39 | K18: انحراف
A20: شفت 2 | B20: 586.65 | D20: شفت 1 | E20: جبهه کاری حفاری | F20: =(LOOKUP(DATA!D10,DATA!K2:K1494,DATA!L2:L1494))+DATA!E10/100 -> 585.8 | G20: =(LOOKUP(DATA!F10,DATA!K2:K1494,DATA!L2:L1494))+DATA!G10/100 -> 584.95 | H20: =F20-G20 -> 0.85 | I20: =B20-G20 -> 1.7 | L20: 7 | M20: 6 | N20: 5 | O20: 4 | P20: 3 | Q20: 2 | R20: 1
K21: انحراف | AB21: =RAND()*(9-3) -> 0.85250771 | AC21: =RAND()*(9-3) -> 1.6647372 | AD21: =#REF! -> #REF! | AE21: =RAND()*(9-3) -> 5.4971735 | AF21: =RAND()*(9-3) -> 2.0850217 | AG21: =RAND()*(9-3) -> 5.5484906 | AH21: =RAND()*(9-3) -> 2.7177566 | AN21: =L21 -> 0 | AO21: =M21 -> 0 | AP21: =N21 -> 0 | AQ21: =O21 -> 0 | AR21: =P21 -> 0 | AS21: =Q21 -> 0 | AT21: =R21 -> 0
E23: نصب 3D یا قاب | F23: =F20 -> 585.8 | G23: =G20 -> 584.95 | H23: =H20 -> 0.85 | I23: =I20 -> 1.7 | K23: ریزش | AN23: =L29 -> 0 | AO23: =M29 -> 0 | AP23: =N29 -> 0 | AQ23: =O29 -> 0 | AR23: =P29 -> 0 | AS23: =Q29 -> 0 | AT23: =R29 -> 0
L25: 7 | M25: 6 | N25: 5 | O25: 4 | P25: 3 | Q25: 2 | R25: 1
E26: اجرای شاتکریت نهائی | F26: =F20 -> 585.8 | G26: =G20 -> 584.95 | H26: =H20 -> 0.85 | I26: =I20 -> 1.7 | K26: انحراف
C28: =B36-B20 -> 323.15 | D28: شفت 3 | E28: جبهه کاری حفاری | F28: =(LOOKUP(DATA!D13,DATA!K2:K1494,DATA!L2:L1494))+DATA!E13/100 -> 588.25 | G28: =(LOOKUP(DATA!F13,DATA!K2:K1494,DATA!L2:L1494))+DATA!G13/100 -> 588.25 | H28: =G28-F28 -> 0 | I28: =G28-B20 -> 1.6 | J28: =(B36-B20)-(H36+H28) -> 323.15 | L28: 7 | M28: 6 | N28: 5 | O28: 4 | P28: 3 | Q28: 2 | R28: 1
K29: انحراف
E31: نصب 3D یا قاب | F31: =F28 -> 588.25 | G31: =G28 -> 588.25 | H31: =H28 -> 0 | I31: =I28 -> 1.6 | K31: ریزش
L33: 7 | M33: 6 | N33: 5 | O33: 4 | P33: 3 | Q33: 2 | R33: 1
E34: اجرای شاتکریت نهائی | F34: =F28 -> 588.25 | G34: =G28 -> 588.25 | H34: =H28 -> 0 | I34: =I28 -> 1.6 | K34: انحراف
A36: شفت 3 | B36: 909.8 | D36: شفت3 | E36: جبهه کاری حفاری | F36: =(LOOKUP(DATA!D16,DATA!K2:K1494,DATA!L2:L1494))+DATA!E16/100 -> 909.8 | G36: =(LOOKUP(DATA!F16,DATA!K2:K1494,DATA!L2:L1494))+DATA!G16/100 -> 909.8 | H36: =F36-G36 -> 0 | I36: =B36-G36 -> -1.0004442e-11 | L36: 7 | M36: 6 | N36: 5 | O36: 4 | P36: 3 | Q36: 2 | R36: 1
K37: انحراف
E39: نصب 3D یا قاب | F39: =F36 -> 909.8 | G39: =G36 -> 909.8 | H39: =H36 -> 0 | I39: =I36 -> -1.0004442e-11 | K39: ریزش
L41: 1 | M41: 6 | N41: 5 | O41: 4 | P41: 3 | Q41: 2 | R41: 1
E42: اجرای شاتکریت نهائی | F42: =F39 -> 909.8 | G42: =G39 -> 909.8 | H42: =H36 -> 0 | I42: =I36 -> -1.0004442e-11 | K42: انحراف
C44: =B52-B36 -> 290.2 | D44: شفت 4 | E44: جبهه کاری حفاری | F44: =(LOOKUP(DATA!D19,DATA!K2:K1494,DATA!L2:L1494))+DATA!E19/100 -> 909.8 | G44: =(LOOKUP(DATA!F19,DATA!K2:K1494,DATA!L2:L1494))+DATA!G19/100 -> 909.8 | H44: =G44-F44 -> 0 | I44: =G44-B36 -> 1.0004442e-11 | J44: =(B52-B36)+(I52+I44) -> 290.2 | L44: 7 | M44: 6 | N44: 5 | O44: 4 | P44: 3 | Q44: 2 | R44: 1
K45: انحراف
E47: نصب 3D یا قاب | F47: =F44 -> 909.8 | G47: =G44 -> 909.8 | H47: =H44 -> 0 | I47: =I44 -> 1.0004442e-11 | K47: ریزش
L49: 7 | M49: 6 | N49: 5 | O49: 4 | P49: 3 | Q49: 2 | R49: 1
E50: اجرای شاتکریت نهائی | F50: =F44 -> 909.8 | G50: =G47 -> 909.8 | H50: =G50-F50 -> 0 | I50: =I44 -> 1.0004442e-11 | K50: انحراف
A52: شفت 4 | B52: 1200 | D52: شفت 3 | E52: جبهه کاری حفاری | F52: =(LOOKUP(DATA!D22,DATA!K2:K1494,DATA!L2:L1494))+DATA!E22/100 -> 1200 | G52: =(LOOKUP(DATA!F22,DATA!K2:K1494,DATA!L2:L1494))+DATA!G22/100 -> 1200 | H52: =G52-F52 -> 0 | I52: =G52-B52 -> 0 | L52: 7 | M52: 6 | N52: 5 | O52: 4 | P52: 3 | Q52: 2 | R52: 1
K53: انحراف
E55: نصب 3D یا قاب | F55: =F52 -> 1200 | G55: =G52 -> 1200 | H55: =H52 -> 0 | I55: =I52 -> 0 | K55: ریزش
L57: 7 | M57: 6 | N57: 5 | O57: 4 | P57: 3 | Q57: 2 | R57: 1
...

Sheet COD
N1: DIM | P1: 1 | Q1: 2 | R1: 3 | S1: 4 | T1: 5 | U1: 6 | V1: 7 | AL1: DIM | AN1: 1 | AO1: 2 | AP1: 3 | AQ1: 4 | AR1: 5 | AS1: 6 | AT1: 7 | AV1: =E4 -> 0 | AW1: =F4 -> 0 | AY1: =Y4 -> 5 | AZ1: =Z4 -> 0
M2: 1 | N2: =E4 -> 0 | O2: =F4 -> 0 | P2: ='فرم نقشه برداری'!AT21 -> 0 | Q2: ='فرم نقشه برداری'!AS21 -> 0 | R2: ='فرم نقشه برداری'!AR21 -> 0 | S2: ='فرم نقشه برداری'!AQ21 -> 0 | T2: ='فرم نقشه برداری'!AP21 -> 0 | U2: ='فرم نقشه برداری'!AO21 -> 0 | V2: ='فرم نقشه برداری'!AN21 -> 0 | AK2: 1 | AL2: =Y4 -> 5 | AM2: =Z4 -> 0 | AN2: ='فرم نقشه برداری'!AT23 -> 0 | AO2: ='فرم نقشه برداری'!AS23 -> 0 | AP2: ='فرم نقشه برداری'!AR23 -> 0 | AQ2: ='فرم نقشه برداری'!AQ23 -> 0 | AR2: ='فرم نقشه برداری'!AP23 -> 0 | AS2: ='فرم نقشه برداری'!AO23 -> 0 | AT2: ='فرم نقشه برداری'!AN23 -> 0 | AV2: =E5 -> 0 | AW2: =F5 -> 1.5 | AY2: =Y5 -> 5 | AZ2: =Z5 -> 1.5
A3: کد | B3: شماره | E3: مختصات ک ک | H3: درصد | K3: موقعیت ثابت خاک | N3: =K4 -> 0 | O3: =L4 -> 0 | W3: کد | X3: شماره | Y3: مختصات ک ب | AA3: مختصات خام | AD3: درصد | AG3: مختصات ثابت | AI3: مختصات ثایت خام | AL3: =AG4 -> 5 | AM3: =AH4 -> 0 | AV3: =E6 -> 0.0032 | AW3: =F6 -> 1.5998 | AY3: =Y6 -> 5.0032 | AZ3: =Z6 -> 1.5998
A4: 1 | B4: 1 | E4: =K4+(P2*H4) -> 0 | F4: =L4+(Q2*I4) -> 0 | H4: -0.01 | I4: 0 | K4: 0 | L4: 0 | W4: 1 | X4: 1 | Y4: =AA4+5 -> 5 | Z4: =AB4 -> 0 | AA4: =AI4+(AN2*AD4) -> 0 | AB4: =AJ4+(AO2*AE4) -> 0 | AD4: =H4 -> -0.01 | AE4: =I4 -> 0 | AG4: =AI4+5 -> 5 | AH4: =AJ4 -> 0 | AI4: 0 | AJ4: 0 | AV4: =E7 -> 0.0135 | AW4: =F7 -> 1.6993 | AY4: =Y7 -> 5.0135 | AZ4: =Z7 -> 1.6993
A5: 2 | B5: 2 | E5: =K5+(Q2*H5) -> 0 | F5: =L5+(R2*I5) -> 1.5 | H5: -0.01 | I5: 0 | K5: 0 | L5: 1.5 | M5: 2 | N5: =E5 -> 0 | O5: =F5 -> 1.5 | W5: 2 | X5: 2 | Y5: =AA5+5 -> 5 | Z5: =AB5 -> 1.5 | AA5: =AI5+(AO2*AD5) -> 0 | AB5: =AJ5+(AP2*AE5) -> 1.5 | AD5: -0.01 | AE5: 0 | AG5: =AI5+5 -> 5 | AH5: =AJ5 -> 1.5 | AI5: 0 | AJ5: 1.5 | AK5: 2 | AL5: =Y5 -> 5 | AM5: =Z5 -> 1.5 | AV5: =E8 -> 0.0306 | AW5: =F8 -> 1.7978 | AY5: =Y8 -> 5.0306 | AZ5: =Z8 -> 1.7978
A6: 2 | B6: 3 | E6: =K6+(Q2*H6) -> 0.0032 | F6: =L6+(Q2*I6) -> 1.5998 | H6: -0.00998 | I6: 0.0007 | K6: 0.0032 | L6: 1.5998 | N6: =K5 -> 0 | O6: =L5 -> 1.5 | W6: 2 | X6: 3 | Y6: =AA6+5 -> 5.0032 | Z6: =AB6 -> 1.5998 | AA6: =AI6+(AO2*AD6) -> 0.0032 | AB6: =AJ6+(AO2*AE6) -> 1.5998 | AD6: -0.00998 | AE6: 0.0007 | AG6: =AI6+5 -> 5.0032 | AH6: =AJ6 -> 1.5998 | AI6: 0.0032 | AJ6: 1.5998 | AL6: =AG5 -> 5 | AM6: =AH5 -> 1.5 | AV6: =E9 -> 0.0545 | AW6: =F9 -> 1.8949 | AY6: =Y9 -> 5.0545 | AZ6: =Z9 -> 1.8949
A7: 2 | B7: 4 | E7: =K7+(Q2*H7) -> 0.0135 | F7: =L7+(Q2*I7) -> 1.6993 | H7: -0.0099 | I7: 0.00138 | K7: 0.0135 | L7: 1.6993 | W7: 2 | X7: 4 | Y7: =AA7+5 -> 5.0135 | Z7: =AB7 -> 1.6993 | AA7: =AI7+(AO2*AD7) -> 0.0135 | AB7: =AJ7+(AO2*AE7) -> 1.6993 | AD7: -0.0099 | AE7: 0.00138 | AG7: =AI7+5 -> 5.0135 | AH7: =AJ7 -> 1.6993 | AI7: 0.0135 | AJ7: 1.6993 | AV7: =E10 -> 0.0851 | AW7: =F10 -> 1.9901 | AY7: =Y10 -> 5.0851 | AZ7: =Z10 -> 1.9901
A8: 2 | B8: 5 | E8: =K8+(Q2*H8) -> 0.0306 | F8: =L8+(Q2*I8) -> 1.7978 | H8: -0.00978 | I8: 0.00206 | K8: 0.0306 | L8: 1.7978 | M8: 3 | N8: =E16 -> 0.3973 | O8: =F16 -> 2.4974 | W8: 2 | X8: 5 | Y8: =AA8+5 -> 5.0306 | Z8: =AB8 -> 1.7978 | AA8: =AI8+(AO2*AD8) -> 0.0306 | AB8: =AJ8+(AO2*AE8) -> 1.7978 | AD8: -0.00978 | AE8: 0.00206 | AG8: =AI8+5 -> 5.0306 | AH8: =AJ8 -> 1.7978 | AI8: 0.0306 | AJ8: 1.7978 | AK8: 3 | AL8: =Y16 -> 5.3973 | AM8: =Z16 -> 2.4974 | AV8: =E11 -> 0.1221 | AW8: =F11 -> 2.0829 | AY8: =Y11 -> 5.1221 | AZ8: =Z11 -> 2.0829
A9: 2 | B9: 6 | E9: =K9+(Q2*H9) -> 0.0545 | F9: =L9+(Q2*I9) -> 1.8949 | H9: -0.00962 | I9: 0.00272 | K9: 0.0545 | L9: 1.8949 | N9: =K16 -> 0.3973 | O9: =L16 -> 2.4974 | W9: 2 | X9: 6 | Y9: =AA9+5 -> 5.0545 | Z9: =AB9 -> 1.8949 | AA9: =AI9+(AO2*AD9) -> 0.0545 | AB9: =AJ9+(AO2*AE9) -> 1.8949 | AD9: -0.00962 | AE9: 0.00272 | AG9: =AI9+5 -> 5.0545 | AH9: =AJ9 -> 1.8949 | AI9: 0.0545 | AJ9: 1.8949 | AL9: =AG16 -> 5.3973 | AM9: =AH16 -> 2.4974 | AV9: =E12 -> 0.1654 | AW9: =F12 -> 2.173 | AY9: =Y12 -> 5.1654 | AZ9: =Z12 -> 2.173
A10: 3 | B10: 7 | E10: =K10+(R2*H10) -> 0.0851 | F10: =L10+(R2*I10) -> 1.9901 | H10: -0.00942 | I10: 0.00338 | K10: 0.0851 | L10: 1.9901 | W10: 3 | X10: 7 | Y10: =AA10+5 -> 5.0851 | Z10: =AB10 -> 1.9901 | AA10: =AI10+(AP2*AD10) -> 0.0851 | AB10: =AJ10+(AP2*AE10) -> 1.9901 | AD10: -0.00942 | AE10: 0.00338 | AG10: =AI10+5 -> 5.0851 | AH10: =AJ10 -> 1.9901 | AI10: 0.0851 | AJ10: 1.9901 | AV10: =E13 -> 0.2149 | AW10: =F13 -> 2.26 | AY10: =Y13 -> 5.2149 | AZ10: =Z13 -> 2.26
A11: 3 | B11: 8 | E11: =K11+(R2*H11) -> 0.1221 | F11: =L11+(R2*I11) -> 2.0829 | H11: -0.00916 | I11: 0.00404 | K11: 0.1221 | L11: 2.0829 | M11: 4 | N11: =E28 -> 1.4721 | O11: =F28 -> 2.9498 | W11: 3 | X11: 8 | Y11: =AA11+5 -> 5.1221 | Z11: =AB11 -> 2.0829 | AA11: =AI11+(AP2*AD11) -> 0.1221 | AB11: =AJ11+(AP2*AE11) -> 2.0829 | AD11: -0.00916 | AE11: 0.00404 | AG11: =AI11+5 -> 5.1221 | AH11: =AJ11 -> 2.0829 | AI11: 0.1221 | AJ11: 2.0829 | AK11: 4 | AL11: =Y28 -> 6.4721 | AM11: =Z28 -> 2.9498 | AV11: =E14 -> 0.2702 | AW11: =F14 -> 2.3432 | AY11: =Y14 -> 5.2702 | AZ11: =Z14 -> 2.3432
A12: 3 | B12: 9 | E12: =K12+(R2*H12) -> 0.1654 | F12: =L12+(R2*I12) -> 2.173 | H12: -0.00886 | I12: 0.00466 | K12: 0.1654 | L12: 2.173 | N12: =K28 -> 1.4721 | O12: =L28 -> 2.9498 | W12: 3 | X12: 9 | Y12: =AA12+5 -> 5.1654 | Z12: =AB12 -> 2.173 | AA12: =AI12+(AP2*AD12) -> 0.1654 | AB12: =AJ12+(AP2*AE12) -> 2.173 | AD12: -0.00886 | AE12: 0.00466 | AG12: =AI12+5 -> 5.1654 | AH12: =AJ12 -> 2.173 | AI12: 0.1654 | AJ12: 2.173 | AL12: =AG28 -> 6.4721 | AM12: =AH28 -> 2.9498 | AV12: =E15 -> 0.3311 | AW12: =F15 -> 2.4225 | AY12: =Y15 -> 5.3311 | AZ12: =Z15 -> 2.4225
A13: 3 | B13: 10 | E13: =K13+(R2*H13) -> 0.2149 | F13: =L13+(R2*I13) -> 2.26 | H13: -0.00852 | I13: 0.00524 | K13: 0.2149 | L13: 2.26 | W13: 3 | X13: 10 | Y13: =AA13+5 -> 5.2149 | Z13: =AB13 -> 2.26 | AA13: =AI13+(AP2*AD13) -> 0.2149 | AB13: =AJ13+(AP2*AE13) -> 2.26 | AD13: -0.00852 | AE13: 0.00524 | AG13: =AI13+5 -> 5.2149 | AH13: =AJ13 -> 2.26 | AI13: 0.2149 | AJ13: 2.26 | AV13: =E16 -> 0.3973 | AW13: =F16 -> 2.4974 | AY13: =Y16 -> 5.3973 | AZ13: =Z16 -> 2.4974
A14: 3 | B14: 11 | E14: =K14+(R2*H14) -> 0.2702 | F14: =L14+(S2*I14) -> 2.3432 | H14: -0.00814 | I14: 0.00582 | K14: 0.2702 | L14: 2.3432 | M14: 5 | N14: =E39 -> 2.4633 | O14: =F39 -> 2.5368 | W14: 3 | X14: 11 | Y14: =AA14+5 -> 5.2702 | Z14: =AB14 -> 2.3432 | AA14: =AI14+(AP2*AD14) -> 0.2702 | AB14: =AJ14+(AQ2*AE14) -> 2.3432 | AD14: -0.00814 | AE14: 0.00582 | AG14: =AI14+5 -> 5.2702 | AH14: =AJ14 -> 2.3432 | AI14: 0.2702 | AJ14: 2.3432 | AK14: 5 | AL14: =Y39 -> 7.4633 | AM14: =Z39 -> 2.5368 | AV14: =E17 -> 0.4686 | AW14: =F17 -> 2.5676 | AY14: =Y17 -> 5.4686 | AZ14: =Z17 -> 2.5676
A15: 3 | B15: 12 | E15: =K15+(R2*H15) -> 0.3311 | F15: =L15+(R2*I15) -> 2.4225 | H15: -0.00772 | I15: 0.00636 | K15: 0.3311 | L15: 2.4225 | N15: =K39 -> 2.4633 | O15: =L39 -> 2.5368 | W15: 3 | X15: 12 | Y15: =AA15+5 -> 5.3311 | Z15: =AB15 -> 2.4225 | AA15: =AI15+(AP2*AD15) -> 0.3311 | AB15: =AJ15+(AP2*AE15) -> 2.4225 | AD15: -0.00772 | AE15: 0.00636 | AG15: =AI15+5 -> 5.3311 | AH15: =AJ15 -> 2.4225 | AI15: 0.3311 | AJ15: 2.4225 | AL15: =AG39 -> 7.4633 | AM15: =AH39 -> 2.5368 | AV15: =E18 -> 0.5445 | AW15: =F18 -> 2.6326 | AY15: =Y18 -> 5.5445 | AZ15: =Z18 -> 2.6326
A16: 3 | B16: 13 | E16: =K16+(R2*H16) -> 0.3973 | F16: =L16+(R2*I16) -> 2.4974 | H16: -0.00726 | I16: 0.00688 | K16: 0.3973 | L16: 2.4974 | W16: 3 | X16: 13 | Y16: =AA16+5 -> 5.3973 | Z16: =AB16 -> 2.4974 | AA16: =AI16+(AP2*AD16) -> 0.3973 | AB16: =AJ16+(AP2*AE16) -> 2.4974 | AD16: -0.00726 | AE16: 0.00688 | AG16: =AI16+5 -> 5.3973 | AH16: =AJ16 -> 2.4974 | AI16: 0.3973 | AJ16: 2.4974 | AV16: =E19 -> 0.6247 | AW16: =F19 -> 2.6923 | AY16: =Y19 -> 5.6247 | AZ16: =Z19 -> 2.6923
A17: 3 | B17: 14 | E17: =K17+(R2*H17) -> 0.4686 | F17: =L17+(R2*I17) -> 2.5676 | H17: -0.00678 | I17: 0.00736 | K17: 0.4686 | L17: 2.5676 | M17: 6 | N17: =E51 -> 2.9 | O17: =F51 -> 1.5 | W17: 3 | X17: 14 | Y17: =AA17+5 -> 5.4686 | Z17: =AB17 -> 2.5676 | AA17: =AI17+(AP2*AD17) -> 0.4686 | AB17: =AJ17+(AP2*AE17) -> 2.5676 | AD17: -0.00678 | AE17: 0.00736 | AG17: =AI17+5 -> 5.4686 | AH17: =AJ17 -> 2.5676 | AI17: 0.4686 | AJ17: 2.5676 | AK17: 6 | AL17: =Y51 -> 7.9 | AM17: =Z51 -> 1.5 | AV17: =E20 -> 0.7088 | AW17: =F20 -> 2.7463 | AY17: =Y20 -> 5.7088 | AZ17: =Z20 -> 2.7463
A18: 3 | B18: 15 | E18: =K18+(R2*H18) -> 0.5445 | F18: =L18+(R2*I18) -> 2.6326 | H18: -0.00624 | I18: 0.00782 | K18: 0.5445 | L18: 2.6326 | N18: =K51 -> 2.9 | O18: =L51 -> 1.5 | W18: 3 | X18: 15 | Y18: =AA18+5 -> 5.5445 | Z18: =AB18 -> 2.6326 | AA18: =AI18+(AP2*AD18) -> 0.5445 | AB18: =AJ18+(AP2*AE18) -> 2.6326 | AD18: -0.00624 | AE18: 0.00782 | AG18: =AI18+5 -> 5.5445 | AH18: =AJ18 -> 2.6326 | AI18: 0.5445 | AJ18: 2.6326 | AL18: =AG51 -> 7.9 | AM18: =AH51 -> 1.5 | AV18: =E21 -> 0.7965 | AW18: =F21 -> 2.7944 | AY18: =Y21 -> 5.7965 | AZ18: =Z21 -> 2.7944
A19: 3 | B19: 16 | E19: =K19+(R2*H19) -> 0.6247 | F19: =L19+(R2*I19) -> 2.6923 | H19: -0.0057 | I19: 0.00822 | K19: 0.6247 | L19: 2.6923 | W19: 3 | X19: 16 | Y19: =AA19+5 -> 5.6247 | Z19: =AB19 -> 2.6923 | AA19: =AI19+(AP2*AD19) -> 0.6247 | AB19: =AJ19+(AP2*AE19) -> 2.6923 | AD19: -0.0057 | AE19: 0.00822 | AG19: =AI19+5 -> 5.6247 | AH19: =AJ19 -> 2.6923 | AI19: 0.6247 | AJ19: 2.6923 | AV19: =E22 -> 0.8872 | AW19: =F22 -> 2.8364 | AY19: =Y22 -> 5.8872 | AZ19: =Z22 -> 2.8364
A20: 3 | B20: 17 | E20: =K20+(R2*H20) -> 0.7088 | F20: =L20+(R2*I20) -> 2.7463 | H20: -0.0051 | I20: 0.0086 | K20: 0.7088 | L20: 2.7463 | M20: 7 | N20: =E52 -> 2.9 | O20: =F52 -> 0 | W20: 3 | X20: 17 | Y20: =AA20+5 -> 5.7088 | Z20: =AB20 -> 2.7463 | AA20: =AI20+(AP2*AD20) -> 0.7088 | AB20: =AJ20+(AP2*AE20) -> 2.7463 | AD20: -0.0051 | AE20: 0.0086 | AG20: =AI20+5 -> 5.7088 | AH20: =AJ20 -> 2.7463 | AI20: 0.7088 | AJ20: 2.7463 | AK20: 7 | AL20: =Y52 -> 7.9 | AM20: =Z52 -> 0 | AV20: =E23 -> 0.9807 | AW20: =F23 -> 2.872 | AY20: =Y23 -> 5.9807 | AZ20: =Z23 -> 2.872
A21: 3 | B21: 18 | E21: =K21+(R2*H21) -> 0.7965 | F21: =L21+(R2*I21) -> 2.7944 | H21: -0.00452 | I21: 0.00894 | K21: 0.7965 | L21: 2.7944 | N21: =K52 -> 2.9 | O21: =L52 -> 0 | W21: 3 | X21: 18 | Y21: =AA21+5 -> 5.7965 | Z21: =AB21 -> 2.7944 | AA21: =AI21+(AP2*AD21) -> 0.7965 | AB21: =AJ21+(AP2*AE21) -> 2.7944 | AD21: -0.00452 | AE21: 0.00894 | AG21: =AI21+5 -> 5.7965 | AH21: =AJ21 -> 2.7944 | AI21: 0.7965 | AJ21: 2.7944 | AL21: =AG52 -> 7.9 | AM21: =AH52 -> 0 | AV21: =E24 -> 1.0763 | AW21: =F24 -> 2.901 | AY21: =Y24 -> 6.0763 | AZ21: =Z24 -> 2.901
A22: 4 | B22: 19 | E22: =K22+(S2*H22) -> 0.8872 | F22: =L22+(S2*I22) -> 2.8364 | H22: -0.00388 | I22: 0.00922 | K22: 0.8872 | L22: 2.8364 | W22: 4 | X22: 19 | Y22: =AA22+5 -> 5.8872 | Z22: =AB22 -> 2.8364 | AA22: =AI22+(AQ2*AD22) -> 0.8872 | AB22: =AJ22+(AQ2*AE22) -> 2.8364 | AD22: -0.00388 | AE22: 0.00922 | AG22: =AI22+5 -> 5.8872 | AH22: =AJ22 -> 2.8364 | AI22: 0.8872 | AJ22: 2.8364 | AV22: =E25 -> 1.1738 | AW22: =F25 -> 2.9234 | AY22: =Y25 -> 6.1738 | AZ22: =Z25 -> 2.9234
A23: 4 | B23: 20 | E23: =K23+(R2*H23) -> 0.9807 | F23: =L23+(S2*I23) -> 2.872 | H23: -0.00324 | I23: 0.00946 | K23: 0.9807 | L23: 2.872 | W23: 4 | X23: 20 | Y23: =AA23+5 -> 5.9807 | Z23: =AB23 -> 2.872 | AA23: =AI23+(AP2*AD23) -> 0.9807 | AB23: =AJ23+(AQ2*AE23) -> 2.872 | AD23: -0.00324 | AE23: 0.00946 | AG23: =AI23+5 -> 5.9807 | AH23: =AJ23 -> 2.872 | AI23: 0.9807 | AJ23: 2.872 | AV23: =E26 -> 1.2725 | AW23: =F26 -> 2.9391 | AY23: =Y26 -> 6.2725 | AZ23: =Z26 -> 2.9391
A24: 4 | B24: 21 | E24: =K24+(S2*H24) -> 1.0763 | F24: =L24+(S2*I24) -> 2.901 | H24: -0.00258 | I24: 0.00966 | K24: 1.0763 | L24: 2.901 | W24: 4 | X24: 21 | Y24: =AA24+5 -> 6.0763 | Z24: =AB24 -> 2.901 | AA24: =AI24+(AQ2*AD24) -> 1.0763 | AB24: =AJ24+(AQ2*AE24) -> 2.901 | AD24: -0.00258 | AE24: 0.00966 | AG24: =AI24+5 -> 6.0763 | AH24: =AJ24 -> 2.901 | AI24: 1.0763 | AJ24: 2.901 | AV24: =E27 -> 1.3721 | AW24: =F27 -> 2.9478 | AY24: =Y27 -> 6.3721 | AZ24: =Z27 -> 2.9478
A25: 4 | B25: 22 | E25: =K25+(S2*H25) -> 1.1738 | F25: =L25+(S2*I25) -> 2.9234 | H25: -0.00192 | I25: 0.00982 | K25: 1.1738 | L25: 2.9234 | W25: 4 | X25: 22 | Y25: =AA25+5 -> 6.1738 | Z25: =AB25 -> 2.9234 | AA25: =AI25+(AQ2*AD25) -> 1.1738 | AB25: =AJ25+(AQ2*AE25) -> 2.9234 | AD25: -0.00192 | AE25: 0.00982 | AG25: =AI25+5 -> 6.1738 | AH25: =AJ25 -> 2.9234 | AI25: 1.1738 | AJ25: 2.9234 | AV25: =E28 -> 1.4721 | AW25: =F28 -> 2.9498 | AY25: =Y28 -> 6.4721 | AZ25: =Z28 -> 2.9498
A26: 4 | B26: 23 | E26: =K26+(S2*H26) -> 1.2725 | F26: =L26+(S2*I26) -> 2.9391 | H26: -0.00122 | I26: 0.00992 | K26: 1.2725 | L26: 2.9391 | W26: 4 | X26: 23 | Y26: =AA26+5 -> 6.2725 | Z26: =AB26 -> 2.9391 | AA26: =AI26+(AQ2*AD26) -> 1.2725 | AB26: =AJ26+(AQ2*AE26) -> 2.9391 | AD26: -0.00122 | AE26: 0.00992 | AG26: =AI26+5 -> 6.2725 | AH26: =AJ26 -> 2.9391 | AI26: 1.2725 | AJ26: 2.9391 | AV26: =E29 -> 1.5719 | AW26: =F29 -> 2.9448 | AY26: =Y29 -> 6.5719 | AZ26: =Z29 -> 2.9448
A27: 4 | B27: 24 | E27: =K27+(S2*H27) -> 1.3721 | F27: =L27+(S2*I27) -> 2.9478 | H27: -0.00054 | I27: 0.01 | K27: 1.3721 | L27: 2.9478 | W27: 4 | X27: 24 | Y27: =AA27+5 -> 6.3721 | Z27: =AB27 -> 2.9478 | AA27: =AI27+(AQ2*AD27) -> 1.3721 | AB27: =AJ27+(AQ2*AE27) -> 2.9478 | AD27: -0.00054 | AE27: 0.01 | AG27: =AI27+5 -> 6.3721 | AH27: =AJ27 -> 2.9478 | AI27: 1.3721 | AJ27: 2.9478 | AV27: =E30 -> 1.6712 | AW27: =F30 -> 2.9329 | AY27: =Y30 -> 6.6712 | AZ27: =Z30 -> 2.9329
A28: 4 | B28: 25 | E28: =K28+(S2*H28) -> 1.4721 | F28: =L28+(S2*I28) -> 2.9498 | H28: 0.00014 | I28: 0.00998 | K28: 1.4721 | L28: 2.9498 | W28: 4 | X28: 25 | Y28: =AA28+5 -> 6.4721 | Z28: =AB28 -> 2.9498 | AA28: =AI28+(AQ2*AD28) -> 1.4721 | AB28: =AJ28+(AQ2*AE28) -> 2.9498 | AD28: 0.00014 | AE28: 0.00998 | AG28: =AI28+5 -> 6.4721 | AH28: =AJ28 -> 2.9498 | AI28: 1.4721 | AJ28: 2.9498 | AV28: =E31 -> 1.7694 | AW28: =F31 -> 2.9142 | AY28: =Y31 -> 6.7694 | AZ28: =Z31 -> 2.9142
A29: 4 | B29: 26 | E29: =K29+(S2*H29) -> 1.5719 | F29: =L29+(S2*I29) -> 2.9448 | H29: 0.00084 | I29: 0.00996 | K29: 1.5719 | L29: 2.9448 | W29: 4 | X29: 26 | Y29: =AA29+5 -> 6.5719 | Z29: =AB29 -> 2.9448 | AA29: =AI29+(AQ2*AD29) -> 1.5719 | AB29: =AJ29+(AQ2*AE29) -> 2.9448 | AD29: 0.00084 | AE29: 0.00996 | AG29: =AI29+5 -> 6.5719 | AH29: =AJ29 -> 2.9448 | AI29: 1.5719 | AJ29: 2.9448 | AV29: =E32 -> 1.8661 | AW29: =F32 -> 2.8888 | AY29: =Y32 -> 6.8661 | AZ29: =Z32 -> 2.8888
A30: 4 | B30: 27 | E30: =K30+(S2*H30) -> 1.6712 | F30: =L30+(S2*I30) -> 2.9329 | H30: 0.00152 | I30: 0.00988 | K30: 1.6712 | L30: 2.9329 | W30: 4 | X30: 27 | Y30: =AA30+5 -> 6.6712 | Z30: =AB30 -> 2.9329 | AA30: =AI30+(AQ2*AD30) -> 1.6712 | AB30: =AJ30+(AQ2*AE30) -> 2.9329 | AD30: 0.00152 | AE30: 0.00988 | AG30: =AI30+5 -> 6.6712 | AH30: =AJ30 -> 2.9329 | AI30: 1.6712 | AJ30: 2.9329 | AV30: =E33 -> 1.9608 | AW30: =F33 -> 2.8569 | AY30: =Y33 -> 6.9608 | AZ30: =Z33 -> 2.8569
A31: 4 | B31: 28 | E31: =K31+(S2*H31) -> 1.7694 | F31: =L31+(S2*I31) -> 2.9142 | H31: 0.0022 | I31: 0.00976 | K31: 1.7694 | L31: 2.9142 | W31: 4 | X31: 28 | Y31: =AA31+5 -> 6.7694 | Z31: =AB31 -> 2.9142 | AA31: =AI31+(AQ2*AD31) -> 1.7694 | AB31: =AJ31+(AQ2*AE31) -> 2.9142 | AD31: 0.0022 | AE31: 0.00976 | AG31: =AI31+5 -> 6.7694 | AH31: =AJ31 -> 2.9142 | AI31: 1.7694 | AJ31: 2.9142 | AV31: =E34 -> 2.0531 | AW31: =F34 -> 2.8184 | AY31: =Y34 -> 7.0531 | AZ31: =Z34 -> 2.8184
A32: 4 | B32: 29 | E32: =K32+(S2*H32) -> 1.8661 | F32: =L32+(S2*I32) -> 2.8888 | H32: 0.00288 | I32: 0.00958 | K32: 1.8661 | L32: 2.8888 | W32: 4 | X32: 29 | Y32: =AA32+5 -> 6.8661 | Z32: =AB32 -> 2.8888 | AA32: =AI32+(AQ2*AD32) -> 1.8661 | AB32: =AJ32+(AQ2*AE32) -> 2.8888 | AD32: 0.00288 | AE32: 0.00958 | AG32: =AI32+5 -> 6.8661 | AH32: =AJ32 -> 2.8888 | AI32: 1.8661 | AJ32: 2.8888 | AV32: =E35 -> 2.1426 | AW32: =F35 -> 2.7737 | AY32: =Y35 -> 7.1426 | AZ32: =Z35 -> 2.7737
A33: 5 | B33: 30 | E33: =K33+(T2*H33) -> 1.9608 | F33: =L33+(T2*I33) -> 2.8569 | H33: 0.00354 | I33: 0.00934 | K33: 1.9608 | L33: 2.8569 | W33: 5 | X33: 30 | Y33: =AA33+5 -> 6.9608 | Z33: =AB33 -> 2.8569 | AA33: =AI33+(AR2*AD33) -> 1.9608 | AB33: =AJ33+(AR2*AE33) -> 2.8569 | AD33: 0.00354 | AE33: 0.00934 | AG33: =AI33+5 -> 6.9608 | AH33: =AJ33 -> 2.8569 | AI33: 1.9608 | AJ33: 2.8569 | AV33: =E36 -> 2.2287 | AW33: =F36 -> 2.7229 | AY33: =Y36 -> 7.2287 | AZ33: =Z36 -> 2.7229
A34: 5 | B34: 31 | E34: =K34+(T2*H34) -> 2.0531 | F34: =L34+(T2*I34) -> 2.8184 | H34: 0.00416 | I34: 0.0091 | K34: 2.0531 | L34: 2.8184 | W34: 5 | X34: 31 | Y34: =AA34+5 -> 7.0531 | Z34: =AB34 -> 2.8184 | AA34: =AI34+(AR2*AD34) -> 2.0531 | AB34: =AJ34+(AR2*AE34) -> 2.8184 | AD34: 0.00416 | AE34: 0.0091 | AG34: =AI34+5 -> 7.0531 | AH34: =AJ34 -> 2.8184 | AI34: 2.0531 | AJ34: 2.8184 | AV34: =E37 -> 2.3111 | AW34: =F37 -> 2.6663 | AY34: =Y37 -> 7.3111 | AZ34: =Z37 -> 2.6663
A35: 5 | B35: 32 | E35: =K35+(T2*H35) -> 2.1426 | F35: =L35+(T2*I35) -> 2.7737 | H35: 0.00476 | I35: 0.00878 | K35: 2.1426 | L35: 2.7737 | W35: 5 | X35: 32 | Y35: =AA35+5 -> 7.1426 | Z35: =AB35 -> 2.7737 | AA35: =AI35+(AR2*AD35) -> 2.1426 | AB35: =AJ35+(AR2*AE35) -> 2.7737 | AD35: 0.00476 | AE35: 0.00878 | AG35: =AI35+5 -> 7.1426 | AH35: =AJ35 -> 2.7737 | AI35: 2.1426 | AJ35: 2.7737 | AV35: =E38 -> 2.3894 | AW35: =F38 -> 2.6042 | AY35: =Y38 -> 7.3894 | AZ35: =Z38 -> 2.6042
A36: 5 | B36: 33 | E36: =K36+(T2*H36) -> 2.2287 | F36: =L36+(T2*I36) -> 2.7229 | H36: 0.00536 | I36: 0.00844 | K36: 2.2287 | L36: 2.7229 | W36: 5 | X36: 33 | Y36: =AA36+5 -> 7.2287 | Z36: =AB36 -> 2.7229 | AA36: =AI36+(AR2*AD36) -> 2.2287 | AB36: =AJ36+(AR2*AE36) -> 2.7229 | AD36: 0.00536 | AE36: 0.00844 | AG36: =AI36+5 -> 7.2287 | AH36: =AJ36 -> 2.7229 | AI36: 2.2287 | AJ36: 2.7229 | AV36: =E39 -> 2.4633 | AW36: =F39 -> 2.5368 | AY36: =Y39 -> 7.4633 | AZ36: =Z39 -> 2.5368
A37: 5 | B37: 34 | E37: =K37+(T2*H37) -> 2.3111 | F37: =L37+(T2*I37) -> 2.6663 | H37: 0.00594 | I37: 0.00806 | K37: 2.3111 | L37: 2.6663 | W37: 5 | X37: 34 | Y37: =AA37+5 -> 7.3111 | Z37: =AB37 -> 2.6663 | AA37: =AI37+(AR2*AD37) -> 2.3111 | AB37: =AJ37+(AR2*AE37) -> 2.6663 | AD37: 0.00594 | AE37: 0.00806 | AG37: =AI37+5 -> 7.3111 | AH37: =AJ37 -> 2.6663 | AI37: 2.3111 | AJ37: 2.6663 | AV37: =E40 -> 2.5323 | AW37: =F40 -> 2.4645 | AY37: =Y40 -> 7.5323 | AZ37: =Z40 -> 2.4645
A38: 5 | B38: 35 | E38: =K38+(T2*H38) -> 2.3894 | F38: =L38+(T2*I38) -> 2.6042 | H38: 0.00648 | I38: 0.00762 | K38: 2.3894 | L38: 2.6042 | W38: 5 | X38: 35 | Y38: =AA38+5 -> 7.3894 | Z38: =AB38 -> 2.6042 | AA38: =AI38+(AR2*AD38) -> 2.3894 | AB38: =AJ38+(AR2*AE38) -> 2.6042 | AD38: 0.00648 | AE38: 0.00762 | AG38: =AI38+5 -> 7.3894 | AH38: =AJ38 -> 2.6042 | AI38: 2.3894 | AJ38: 2.6042 | AV38: =E41 -> 2.5962 | AW38: =F41 -> 2.3876 | AY38: =Y41 -> 7.5962 | AZ38: =Z41 -> 2.3876
A39: 5 | B39: 36 | E39: =K39+(T2*H39) -> 2.4633 | F39: =L39+(U2*I39) -> 2.5368 | H39: 0.007 | I39: 0.007 | K39: 2.4633 | L39: 2.5368 | W39: 5 | X39: 36 | Y39: =AA39+5 -> 7.4633 | Z39: =AB39 -> 2.5368 | AA39: =AI39+(AR2*AD39) -> 2.4633 | AB39: =AJ39+(AS2*AE39) -> 2.5368 | AD39: 0.007 | AE39: 0.007 | AG39: =AI39+5 -> 7.4633 | AH39: =AJ39 -> 2.5368 | AI39: 2.4633 | AJ39: 2.5368 | AV39: =E42 -> 2.6547 | AW39: =F42 -> 2.3065 | AY39: =Y42 -> 7.6547 | AZ39: =Z42 -> 2.3065
A40: 5 | B40: 37 | E40: =K40+(T2*H40) -> 2.5323 | F40: =L40+(T2*I40) -> 2.4645 | H40: 0.00748 | I40: 0.00666 | K40: 2.5323 | L40: 2.4645 | W40: 5 | X40: 37 | Y40: =AA40+5 -> 7.5323 | Z40: =AB40 -> 2.4645 | AA40: =AI40+(AR2*AD40) -> 2.5323 | AB40: =AJ40+(AR2*AE40) -> 2.4645 | AD40: 0.00748 | AE40: 0.00666 | AG40: =AI40+5 -> 7.5323 | AH40: =AJ40 -> 2.4645 | AI40: 2.5323 | AJ40: 2.4645 | AV40: =E43 -> 2.7074 | AW40: =F43 -> 2.2215 | AY40: =Y43 -> 7.7074 | AZ40: =Z43 -> 2.2215
...

Sheet DATA
D1: تایخ | E1: 06/07 | F1: 1405 | K1: نقطه | L1: کیلومتراژ | M1: X | N1: Y | O1: Z | U1: روز | V1: تاریخ
A2: پروژه احداث تونل و کانال کابل ارتباطی | D2: ایام هفته : | E2: =LOOKUP(E1,V:V,U:U) -> شنبه | K2: 200 | L2: 227 | M2: 733569 | N2: 4017781.7 | O2: 962.926 | U2: شنبه | V2: 01/01
A3: شفت | B3: سمت | C3: فعالیت | D3: نقطه قبلی | E3: طول | F3: نقطه فعلی | G3: طول | K3: 201 | L3: 228.2 | M3: 733568.26 | N3: 4017782.6 | O3: 962.918 | U3: یکشنبه | V3: 01/02
A4: شفت 1 | B4: 1-0 | C4: جبهه کاری حفاری | D4: 306 | E4: 110 | F4: =D4-I4 -> 306 | G4: 14 | I4: 0 | J4: =F4+1 -> 307 | K4: 202 | L4: 229.4 | M4: 733567.53 | N4: 4017783.6 | O4: 962.914 | U4: دوشنبه | V4: 01/03
K5: 203 | L5: 230.6 | M5: 733566.79 | N5: 4017784.5 | O5: 962.909 | U5: سه شنبه | V5: 01/04
K6: 204 | L6: 231.8 | M6: 733566.06 | N6: 4017785.5 | O6: 962.905 | U6: چهارشنبه | V6: 01/05
B7: 1-2 | C7: جبهه کاری حفاری | D7: 316 | E7: 11 | F7: =D7+I7 -> 317 | G7: 9 | I7: 1 | J7: =F7+1 -> 318 | K7: 205 | L7: 233 | M7: 733565.32 | N7: 4017786.4 | O7: 962.9 | U7: پنج شنبه | V7: 01/06
K8: 206 | L8: 234.2 | M8: 733564.58 | N8: 4017787.4 | O8: 962.896 | U8: جمعه | V8: 01/07
K9: 207 | L9: 235.4 | M9: 733563.85 | N9: 4017788.3 | O9: 962.891 | U9: شنبه | V9: 01/08
A10: شفت 2 | B10: 2-1 | C10: جبهه کاری حفاری | D10: 497 | E10: 0 | F10: =D10-I10 -> 496 | G10: 35 | I10: 1 | J10: =F10+1 -> 497 | K10: 208 | L10: 236.6 | M10: 733563.11 | N10: 4017789.3 | O10: 962.887 | U10: یکشنبه | V10: 01/09
H11: 0 | K11: 209 | L11: 237.8 | M11: 733562.38 | N11: 4017790.2 | O11: 962.883 | U11: دوشنبه | V11: 01/10
K12: 210 | L12: 239 | M12: 733561.64 | N12: 4017791.2 | O12: 962.883 | U12: سه شنبه | V12: 01/11
B13: 2-3 | C13: جبهه کاری حفاری | D13: 499 | E13: 5 | F13: =D13+I13 -> 499 | G13: 5 | I13: 0 | J13: =F13+1 -> 500 | K13: 211 | L13: 240.2 | M13: 733560.91 | N13: 4017792.1 | O13: 962.874 | U13: چهارشنبه | V13: 01/12
K14: 212 | L14: 241.4 | M14: 733560.17 | N14: 4017793.1 | O14: 962.869 | U14: پنج شنبه | V14: 01/13
K15: 213 | L15: 242.6 | M15: 733559.44 | N15: 4017794 | O15: 962.865 | U15: جمعه | V15: 01/14
A16: شفت 3 | B16: 3-2 | C16: جبهه کاری حفاری | D16: 767 | E16: 0 | F16: =D16-I16 -> 767 | G16: 0 | I16: 0 | J16: =F16+1 -> 768 | K16: 214 | L16: 243.8 | M16: 733558.7 | N16: 4017795 | O16: 962.86 | U16: شنبه | V16: 01/15
H17: 1 | K17: 215 | L17: 245 | M17: 733557.96 | N17: 4017795.9 | O17: 962.856 | U17: یکشنبه | V17: 01/16
K18: 216 | L18: 246.2 | M18: 733557.23 | N18: 4017796.9 | O18: 962.851 | U18: دوشنبه | V18: 01/17
B19: 3-4 | C19: جبهه کاری حفاری | D19: 767 | E19: 0 | F19: =D19+I19 -> 767 | G19: 0 | I19: 0 | J19: =F19+1 -> 768 | K19: 217 | L19: 247.4 | M19: 733556.49 | N19: 4017797.8 | O19: 962.847 | U19: دوشنبه | V19: 01/18
K20: 218 | L20: 248.6 | M20: 733555.76 | N20: 4017798.8 | O20: 962.842 | U20: سه شنبه | V20: 01/19
K21: 219 | L21: 249.8 | M21: 733555.02 | N21: 4017799.7 | O21: 962.838 | U21: چهارشنبه | V21: 01/20
A22: شفت 4 | B22: 4-3 | C22: جبهه کاری حفاری | D22: 5000 | E22: 0 | F22: =D22-I22 -> 5000 | G22: 0 | I22: 0 | J22: =F22+1 -> 5001 | K22: 220 | L22: 251 | M22: 733554.29 | N22: 4017800.7 | O22: 962.852 | U22: پنج شنبه | V22: 01/21
H23: 2 | K23: 221 | L23: 252.2 | M23: 733553.55 | N23: 4017801.6 | O23: 962.87 | U23: جمعه | V23: 01/28
K24: 222 | L24: 253.4 | M24: 733552.82 | N24: 4017802.6 | O24: 962.888 | U24: شنبه | V24: 01/29
B25: 4-5 | C25: جبهه کاری حفاری | D25: 5000 | E25: 0 | F25: =D25+I25 -> 5000 | G25: 0 | I25: 0 | J25: =F25+1 -> 5001 | K25: 223 | L25: 254.6 | M25: 733552.08 | N25: 4017803.5 | O25: 962.905 | U25: یکشنبه | V25: 01/30
K26: 224 | L26: 255.8 | M26: 733551.31 | N26: 4017804.4 | O26: 962.923 | U26: دوشنبه | V26: 01/31
K27: 225 | L27: 257 | M27: 733550.55 | N27: 4017805.4 | O27: 962.941 | U27: سه شنبه | V27: 02/01
K28: 226 | L28: 258.2 | M28: 733549.78 | N28: 4017806.3 | O28: 962.959 | U28: چهارشنبه | V28: 02/02
F29: h | K29: 227 | L29: 259.4 | M29: 733549.02 | N29: 4017807.2 | O29: 962.977 | U29: پنج شنبه | V29: 02/03
K30: 228 | L30: 260.6 | M30: 733548.25 | N30: 4017808.1 | O30: 962.995 | U30: جمعه | V30: 02/04
K31: 229 | L31: 261.8 | M31: 733547.48 | N31: 4017809 | O31: 963.012 | U31: شنبه | V31: 02/05
K32: 230 | L32: 263 | M32: 733546.72 | N32: 4017810 | O32: 963.03 | U32: یکشنبه | V32: 02/06
K33: 231 | L33: 264.2 | M33: 733545.95 | N33: 4017810.9 | O33: 963.048 | U33: دوشنبه | V33: 02/07
K34: 232 | L34: 265.4 | M34: 733545.19 | N34: 4017811.8 | O34: 963.066 | U34: سه شنبه | V34: 02/08
K35: 233 | L35: 266.6 | M35: 733544.42 | N35: 4017812.7 | O35: 963.084 | U35: چهارشنبه | V35: 02/09
K36: 234 | L36: 267.8 | M36: 733543.65 | N36: 4017813.7 | O36: 963.102 | U36: پنج شنبه | V36: 02/10
K37: 235 | L37: 269 | M37: 733542.89 | N37: 4017814.6 | O37: 963.119 | U37: جمعه | V37: 02/11
K38: 236 | L38: 270.2 | M38: 733542.12 | N38: 4017815.5 | O38: 963.137 | U38: شنبه | V38: 02/12
K39: 237 | L39: 271.4 | M39: 733541.36 | N39: 4017816.4 | O39: 963.155 | U39: یکشنبه | V39: 02/13
K40: 238 | L40: 272.6 | M40: 733540.59 | N40: 4017817.4 | O40: 963.173 | U40: دوشنبه | V40: 02/14
...

Sheet POINT
A1: =IF(N1>0,1,0) -> 1 | B1: =SUBSTITUTE(DATA!E1,"/","") -> 0607 | C1: =((LOOKUP(DATA!F4,DATA!K2:K1494,DATA!M2:M1494))) -> 733491.11 | D1: =((LOOKUP(DATA!F4,DATA!K2:K1494,DATA!N2:N1494))) -> 4017882.2 | E1: =((LOOKUP(DATA!F4,DATA!K2:K1494,DATA!O2:O1494))) -> 964.421 | F1: =((LOOKUP(DATA!J4,DATA!K2:K1494,DATA!M2:M1494))) -> 733490.41 | G1: =((LOOKUP(DATA!J4,DATA!K2:K1494,DATA!N2:N1494))) -> 4017883.2 | H1: =((LOOKUP(DATA!J4,DATA!K2:K1494,DATA!O2:O1494))) -> 964.439 | I1: =DATA!G4/100 -> 0.14 | J1: ='فرم نقشه برداری'!X5 -> 354.34 | K1: =IF(SQRT((F1-C1)^2+(G1-D1)^2+(H1-E1)^2)=0,C1,C1+(I1/SQRT((F1-C1)^2+(G1-D1)^2+(H1-E1)^2))*(F1-C1)) -> 733491.03 | L1: =IF(SQRT((F1-C1)^2+(G1-D1)^2+(H1-E1)^2)=0,D1,D1+(I1/SQRT((F1-C1)^2+(G1-D1)^2+(H1-E1)^2))*(G1-D1)) -> 4017882.3 | M1: =IF(SQRT((F1-C1)^2+(G1-D1)^2+(H1-E1)^2)=0,E1,E1+(I1/SQRT((F1-C1)^2+(G1-D1)^2+(H1-E1)^2))*(H1-E1)) -> 964.4231 | N1: ='فرم نقشه برداری'!Y5 -> 0.96
A2: =IF(N2>0,1,0) -> 1 | B2: =B1 -> 0607 | C2: =((LOOKUP(DATA!F7,DATA!K2:K1494,DATA!M2:M1494))) -> 733482.55 | D2: =((LOOKUP(DATA!F7,DATA!K2:K1494,DATA!N2:N1494))) -> 4017892.2 | E2: =((LOOKUP(DATA!F7,DATA!K2:K1494,DATA!O2:O1494))) -> 964.541 | F2: =((LOOKUP(DATA!J7,DATA!K2:K1494,DATA!M2:M1494))) -> 733481.68 | G2: =((LOOKUP(DATA!J7,DATA!K2:K1494,DATA!N2:N1494))) -> 4017893 | H2: =((LOOKUP(DATA!J7,DATA!K2:K1494,DATA!O2:O1494))) -> 964.548 | I2: =DATA!G7/100 -> 0.09 | J2: ='فرم نقشه برداری'!X6 -> 367.49 | K2: =IF(SQRT((F2-C2)^2+(G2-D2)^2+(H2-E2)^2)=0,C2,C2+(I2/SQRT((F2-C2)^2+(G2-D2)^2+(H2-E2)^2))*(F2-C2)) -> 733482.49 | L2: =IF(SQRT((F2-C2)^2+(G2-D2)^2+(H2-E2)^2)=0,D2,D2+(I2/SQRT((F2-C2)^2+(G2-D2)^2+(H2-E2)^2))*(G2-D2)) -> 4017892.3 | M2: =IF(SQRT((F2-C2)^2+(G2-D2)^2+(H2-E2)^2)=0,E2,E2+(I2/SQRT((F2-C2)^2+(G2-D2)^2+(H2-E2)^2))*(H2-E2)) -> 964.54153 | N2: ='فرم نقشه برداری'!Y6 -> 1.18
A3: =IF(N3>0,1,0) -> 1 | B3: =B2 -> 0607 | C3: =((LOOKUP(DATA!F10,DATA!K2:K1494,DATA!M2:M1494))) -> 733342.35 | D3: =((LOOKUP(DATA!F10,DATA!K2:K1494,DATA!N2:N1494))) -> 4018057.1 | E3: =((LOOKUP(DATA!F10,DATA!K2:K1494,DATA!O2:O1494))) -> 965.663 | F3: =((LOOKUP(DATA!J10,DATA!K2:K1494,DATA!M2:M1494))) -> 733341.62 | G3: =((LOOKUP(DATA!J10,DATA!K2:K1494,DATA!N2:N1494))) -> 4018058 | H3: =((LOOKUP(DATA!J10,DATA!K2:K1494,DATA!O2:O1494))) -> 965.669 | I3: =DATA!G10/100 -> 0.35 | J3: ='فرم نقشه برداری'!X7 -> 584.95 | K3: =IF(SQRT((F3-C3)^2+(G3-D3)^2+(H3-E3)^2)=0,C3,C3+(I3/SQRT((F3-C3)^2+(G3-D3)^2+(H3-E3)^2))*(F3-C3)) -> 733342.14 | L3: =IF(SQRT((F3-C3)^2+(G3-D3)^2+(H3-E3)^2)=0,D3,D3+(I3/SQRT((F3-C3)^2+(G3-D3)^2+(H3-E3)^2))*(G3-D3)) -> 4018057.3 | M3: =IF(SQRT((F3-C3)^2+(G3-D3)^2+(H3-E3)^2)=0,E3,E3+(I3/SQRT((F3-C3)^2+(G3-D3)^2+(H3-E3)^2))*(H3-E3)) -> 965.66475 | N3: ='فرم نقشه برداری'!Y7 -> 0.85
A4: =IF(N4>0,1,0) -> 0 | B4: =B3 -> 0607 | C4: =((LOOKUP(DATA!F13,DATA!K2:K1494,DATA!M2:M1494))) -> 733340.05 | D4: =((LOOKUP(DATA!F13,DATA!K2:K1494,DATA!N2:N1494))) -> 4018059.8 | E4: =((LOOKUP(DATA!F13,DATA!K2:K1494,DATA!O2:O1494))) -> 965.66 | F4: =((LOOKUP(DATA!J13,DATA!K2:K1494,DATA!M2:M1494))) -> 733339.27 | G4: =((LOOKUP(DATA!J13,DATA!K2:K1494,DATA!N2:N1494))) -> 4018060.7 | H4: =((LOOKUP(DATA!J13,DATA!K2:K1494,DATA!O2:O1494))) -> 965.651 | I4: =DATA!G13/100 -> 0.05 | J4: ='فرم نقشه برداری'!X8 -> 588.25 | K4: =IF(SQRT((F4-C4)^2+(G4-D4)^2+(H4-E4)^2)=0,C4,C4+(I4/SQRT((F4-C4)^2+(G4-D4)^2+(H4-E4)^2))*(F4-C4)) -> 733340.02 | L4: =IF(SQRT((F4-C4)^2+(G4-D4)^2+(H4-E4)^2)=0,D4,D4+(I4/SQRT((F4-C4)^2+(G4-D4)^2+(H4-E4)^2))*(G4-D4)) -> 4018059.9 | M4: =IF(SQRT((F4-C4)^2+(G4-D4)^2+(H4-E4)^2)=0,E4,E4+(I4/SQRT((F4-C4)^2+(G4-D4)^2+(H4-E4)^2))*(H4-E4)) -> 965.65962 | N4: ='فرم نقشه برداری'!Y8 -> 0
A5: =IF(N5>0,1,0) -> 0 | B5: =B4 -> 0607 | C5: =((LOOKUP(DATA!F16,DATA!K2:K1494,DATA!M2:M1494))) -> 733176.94 | D5: =((LOOKUP(DATA!F16,DATA!K2:K1494,DATA!N2:N1494))) -> 4018316.3 | E5: =((LOOKUP(DATA!F16,DATA!K2:K1494,DATA!O2:O1494))) -> 967.881 | F5: =((LOOKUP(DATA!J16,DATA!K2:K1494,DATA!M2:M1494))) -> 733176.94 | G5: =((LOOKUP(DATA!J16,DATA!K2:K1494,DATA!N2:N1494))) -> 4018316.3 | H5: =((LOOKUP(DATA!J16,DATA!K2:K1494,DATA!O2:O1494))) -> 967.874 | I5: =DATA!G16/100 -> 0 | J5: ='فرم نقشه برداری'!X9 -> 909.8 | K5: =IF(SQRT((F5-C5)^2+(G5-D5)^2+(H5-E5)^2)=0,C5,C5+(I5/SQRT((F5-C5)^2+(G5-D5)^2+(H5-E5)^2))*(F5-C5)) -> 733176.94 | L5: =IF(SQRT((F5-C5)^2+(G5-D5)^2+(H5-E5)^2)=0,D5,D5+(I5/SQRT((F5-C5)^2+(G5-D5)^2+(H5-E5)^2))*(G5-D5)) -> 4018316.3 | M5: =IF(SQRT((F5-C5)^2+(G5-D5)^2+(H5-E5)^2)=0,E5,E5+(I5/SQRT((F5-C5)^2+(G5-D5)^2+(H5-E5)^2))*(H5-E5)) -> 967.881 | N5: ='فرم نقشه برداری'!Y9 -> 0
A6: =IF(N6>0,1,0) -> 0 | B6: =B5 -> 0607 | C6: =((LOOKUP(DATA!F19,DATA!K2:K1494,DATA!M2:M1494))) -> 733176.94 | D6: =((LOOKUP(DATA!F19,DATA!K2:K1494,DATA!N2:N1494))) -> 4018316.3 | E6: =((LOOKUP(DATA!F19,DATA!K2:K1494,DATA!O2:O1494))) -> 967.881 | F6: =((LOOKUP(DATA!J19,DATA!K2:K1494,DATA!M2:M1494))) -> 733176.94 | G6: =((LOOKUP(DATA!J19,DATA!K2:K1494,DATA!N2:N1494))) -> 4018316.3 | H6: =((LOOKUP(DATA!J19,DATA!K2:K1494,DATA!O2:O1494))) -> 967.874 | I6: =DATA!G19/100 -> 0 | J6: ='فرم نقشه برداری'!X10 -> 909.8 | K6: =IF(SQRT((F6-C6)^2+(G6-D6)^2+(H6-E6)^2)=0,C6,C6+(I6/SQRT((F6-C6)^2+(G6-D6)^2+(H6-E6)^2))*(F6-C6)) -> 733176.94 | L6: =IF(SQRT((F6-C6)^2+(G6-D6)^2+(H6-E6)^2)=0,D6,D6+(I6/SQRT((F6-C6)^2+(G6-D6)^2+(H6-E6)^2))*(G6-D6)) -> 4018316.3 | M6: =IF(SQRT((F6-C6)^2+(G6-D6)^2+(H6-E6)^2)=0,E6,E6+(I6/SQRT((F6-C6)^2+(G6-D6)^2+(H6-E6)^2))*(H6-E6)) -> 967.881 | N6: ='فرم نقشه برداری'!Y10 -> 0
A7: =IF(N7>0,1,0) -> 0 | B7: =B6 -> 0607 | C7: =((LOOKUP(DATA!F22,DATA!K2:K1494,DATA!M2:M1494))) -> 0 | D7: =((LOOKUP(DATA!F22,DATA!K2:K1494,DATA!N2:N1494))) -> 0 | E7: =((LOOKUP(DATA!F22,DATA!K2:K1494,DATA!O2:O1494))) -> 0 | F7: =((LOOKUP(DATA!J22,DATA!K2:K1494,DATA!M2:M1494))) -> 0 | G7: =((LOOKUP(DATA!J22,DATA!K2:K1494,DATA!N2:N1494))) -> 0 | H7: =((LOOKUP(DATA!J22,DATA!K2:K1494,DATA!O2:O1494))) -> 0 | I7: =DATA!G22/100 -> 0 | J7: ='فرم نقشه برداری'!X11 -> 1200 | K7: =IF(SQRT((F7-C7)^2+(G7-D7)^2+(H7-E7)^2)=0,C7,C7+(I7/SQRT((F7-C7)^2+(G7-D7)^2+(H7-E7)^2))*(F7-C7)) -> 0 | L7: =IF(SQRT((F7-C7)^2+(G7-D7)^2+(H7-E7)^2)=0,D7,D7+(I7/SQRT((F7-C7)^2+(G7-D7)^2+(H7-E7)^2))*(G7-D7)) -> 0 | M7: =IF(SQRT((F7-C7)^2+(G7-D7)^2+(H7-E7)^2)=0,E7,E7+(I7/SQRT((F7-C7)^2+(G7-D7)^2+(H7-E7)^2))*(H7-E7)) -> 0 | N7: ='فرم نقشه برداری'!Y11 -> 0
A8: =IF(N8>0,1,0) -> 0 | B8: =B7 -> 0607 | C8: =((LOOKUP(DATA!F25,DATA!K2:K1494,DATA!M2:M1494))) -> 0 | D8: =((LOOKUP(DATA!F25,DATA!K2:K1494,DATA!N2:N1494))) -> 0 | E8: =((LOOKUP(DATA!F25,DATA!K2:K1494,DATA!O2:O1494))) -> 0 | F8: =((LOOKUP(DATA!J25,DATA!K2:K1494,DATA!M2:M1494))) -> 0 | G8: =((LOOKUP(DATA!J25,DATA!K2:K1494,DATA!N2:N1494))) -> 0 | H8: =((LOOKUP(DATA!J25,DATA!K2:K1494,DATA!O2:O1494))) -> 0 | I8: =DATA!G25/100 -> 0 | J8: ='فرم نقشه برداری'!X12 -> 1200 | K8: =IF(SQRT((F8-C8)^2+(G8-D8)^2+(H8-E8)^2)=0,C8,C8+(I8/SQRT((F8-C8)^2+(G8-D8)^2+(H8-E8)^2))*(F8-C8)) -> 0 | L8: =IF(SQRT((F8-C8)^2+(G8-D8)^2+(H8-E8)^2)=0,D8,D8+(I8/SQRT((F8-C8)^2+(G8-D8)^2+(H8-E8)^2))*(G8-D8)) -> 0 | M8: =IF(SQRT((F8-C8)^2+(G8-D8)^2+(H8-E8)^2)=0,E8,E8+(I8/SQRT((F8-C8)^2+(G8-D8)^2+(H8-E8)^2))*(H8-E8)) -> 0 | N8: ='فرم نقشه برداری'!Y12 -> 0

Sheet وضعیت
A1: 75.95 | B1: =E1-A1 -> 177.63 | E1: 253.58 | F1: =I1-E1 -> 415.92 | I1: 669.5 | J1: =M1-I1 -> 233.26 | M1: 902.76 | N1: =Q1-M1 -> 196.8 | Q1: 1099.56 | R1: =U1-Q1 -> 238.29 | U1: 1337.85 | V1: =V2-U1 -> 148.78 | X1: کیلومتر و فواصل شفت
A2: سه راهی | B2: 75.95 | C2: <KM> | D2: ='فرم نقشه برداری'!Y20 -> 0 | E2: شفت 3 | F2: ='فرم نقشه برداری'!Y21 -> 0 | G2: <KM> | H2: ='فرم نقشه برداری'!Y22 -> 0 | I2: شفت 4 | J2: 760.03 | K2: <KM> | L2: 760.03 | M2: شفت 5 | N2: 1015.23 | O2: <KM> | P2: 1015.23 | Q2: شفت 6 | R2: 1203.16 | S2: <KM> | T2: 1203.16 | U2: شفت 7 | V2: 1486.63 | W2: <KM> | X2: کیلومتر سینه کار
A3: <پیشرفت > | B3: 0 | C3: مانده | D3: =E1-D2 -> 253.58 | E3: <پیشرفت > | F3: =F2-E1 -> -253.58 | G3: مانده | H3: =I1-H2 -> 669.5 | I3: <پیشرفت > | J3: =J2-I1 -> 90.53 | K3: مانده | L3: =M1-L2 -> 142.73 | M3: <پیشرفت > | N3: =N2-M1 -> 112.47 | O3: مانده | P3: =Q1-P2 -> 84.33 | Q3: <پیشرفت > | R3: =R2-Q1 -> 103.6 | S3: مانده | T3: =U1-T2 -> 134.69 | U3: <پیشرفت > | V3: =V2-U1 -> 148.78 | W3: مانده | X3: متراژ پیشرفت
C4: =D2-B2 -> -75.95 | G4: =H2-F2 -> 0 | K4: 0 | O4: 0 | S4: 0 | W4: 0
